Workbook
Name ExternalData_1: Sheet10!$A$1:$B$71
Name ExternalData_1: Sheet11!$A$1:$B$57
Name ExternalData_1: Sheet5!$A$1:$B$51
Name ExternalData_1: Sheet6!$A$1:$B$41

Sheet Todo en 0
A1: 0 | K1: 0.04 | U1: 0.08
A2: uh122 | B2: 0.0025 | C2: -0.37890394 | D2: -1.0970654 | E2: 0.58712744 | F2: 0.19712478 | G2: =C3-C2 -> 0.073452118 | H2: =D3-D2 -> -0.010600339 | I2: =E3-E2 -> -0.01311211 | J2: =F3-F2 -> -0.006557884 | K2: uh122 | L2: 0.0425 | M2: 0.82963601 | N2: -1.2714774 | O2: 0.37138814 | P2: 0.089225035 | Q2: =M3-M2 -> 0.077954971 | R2: =N3-N2 -> -0.011250174 | S2: =O3-O2 -> -0.013915925 | T2: =P3-P2 -> -0.0069599036 | U2: uh122 | V2: 0.0825 | W2: 2.112919 | X2: -1.4566761 | Y2: 0.14230629 | Z2: -0.025347847 | AA2: =W3-W2 -> 0.082822589 | AB2: =X3-X2 -> -0.011952651 | AC2: =Y3-Y2 -> -0.014784855 | AD2: =Z3-Z2 -> -0.0073944898
B3: 0.005 | C3: -0.30545182 | D3: -1.1076657 | E3: 0.57401533 | F3: 0.1905669 | G3: =C4-C3 -> 0.073723403 | H3: =D4-D3 -> -0.010639489 | I3: =E4-E3 -> -0.013160538 | J3: =F4-F3 -> -0.0065821046 | L3: 0.045 | M3: 0.90759098 | N3: -1.2827276 | O3: 0.35747221 | P3: 0.082265131 | Q3: =M4-M3 -> 0.078248211 | R3: =N4-N3 -> -0.011292493 | S3: =O4-O3 -> -0.013968272 | T3: =P4-P3 -> -0.0069860844 | V3: 0.085 | W3: 2.1957416 | X3: -1.4686287 | Y3: 0.12752143 | Z3: -0.032742337 | AA3: =W4-W3 -> 0.083139591 | AB3: =X4-X3 -> -0.011998399 | AC3: =Y4-Y3 -> -0.014841443 | AD3: =Z4-Z3 -> -0.007422792
B4: 0.0075 | C4: -0.23172842 | D4: -1.1183052 | E4: 0.56085479 | F4: 0.18398479 | G4: =C5-C4 -> 0.073996007 | H4: =D5-D4 -> -0.010678831 | I4: =E5-E4 -> -0.013209201 | J4: =F5-F4 -> -0.0066064431 | L4: 0.0475 | M4: 0.98583919 | N4: -1.2940201 | O4: 0.34350394 | P4: 0.075279047 | Q4: =M5-M4 -> 0.078542882 | R4: =N5-N4 -> -0.011335019 | S4: =O5-O4 -> -0.014020874 | T4: =P5-P4 -> -0.0070123929 | V4: 0.0875 | W4: 2.2788811 | X4: -1.4806271 | Y4: 0.11267999 | Z4: -0.040165129 | AA4: =W5-W4 -> 0.083458139 | AB4: =X5-X4 -> -0.012044371 | AC4: =Y5-Y4 -> -0.014898308 | AD4: =Z5-Z4 -> -0.0074512323
B5: 0.01 | C5: -0.15773241 | D5: -1.128984 | E5: 0.54764559 | F5: 0.17737835 | G5: =C6-C5 -> 0.074269939 | H5: =D6-D5 -> -0.010718364 | I5: =E6-E5 -> -0.013258101 | J5: =F6-F5 -> -0.0066309 | L5: 0.05 | M5: 1.0643821 | N5: -1.3053551 | O5: 0.32948307 | P5: 0.068266654 | Q5: =M6-M5 -> 0.078838992 | R5: =N6-N5 -> -0.011377753 | S5: =O6-O5 -> -0.014073733 | T5: =P6-P5 -> -0.0070388299 | V5: 0.09 | W5: 2.3623393 | X5: -1.4926715 | Y5: 0.097781681 | Z5: -0.047616361 | AA5: =W6-W5 -> 0.08377824 | AB5: =X6-X5 -> -0.012090567 | AC5: =Y6-Y5 -> -0.01495545 | AD5: =Z6-Z5 -> -0.0074798113
B6: 0.0125 | C6: -0.083462473 | D6: -1.1397024 | E6: 0.53438749 | F6: 0.17074745 | G6: =C7-C6 -> 0.074545206 | H6: =D7-D6 -> -0.010758089 | I6: =E7-E6 -> -0.01330724 | J6: =F7-F6 -> -0.0066554761 | L6: 0.0525 | M6: 1.1432211 | N6: -1.3167328 | O6: 0.31540933 | P6: 0.061227824 | Q6: =M7-M6 -> 0.079136548 | R6: =N7-N6 -> -0.011420695 | S6: =O7-O6 -> -0.014126851 | T6: =P7-P6 -> -0.007065396 | V6: 0.0925 | W6: 2.4461175 | X6: -1.504762 | Y6: 0.082826231 | Z6: -0.055096172 | AA6: =W7-W6 -> 0.084099901 | AB6: =X7-X6 -> -0.012136988 | AC6: =Y7-Y6 -> -0.015012871 | AD6: =Z7-Z6 -> -0.0075085296
B7: 0.015 | C7: -0.008917267 | D7: -1.1504605 | E7: 0.52108025 | F7: 0.16409197 | G7: =C8-C7 -> 0.074821813 | H7: =D8-D7 -> -0.010798008 | I7: =E8-E7 -> -0.013356617 | J7: =F8-F7 -> -0.0066801718 | L7: 0.055 | M7: 1.2223576 | N7: -1.3281535 | O7: 0.30128248 | P7: 0.054162428 | Q7: =M8-M7 -> 0.079435557 | R7: =N8-N7 -> -0.011463846 | S7: =O8-O7 -> -0.014180228 | T7: =P8-P7 -> -0.0070920919 | V7: 0.095 | W7: 2.5302174 | X7: -1.516899 | Y7: 0.06781336 | Z7: -0.062604702 | AA7: =W8-W7 -> 0.084423131 | AB7: =X8-X7 -> -0.012183635 | AC7: =Y8-Y7 -> -0.015070571 | AD7: =Z8-Z7 -> -0.0075373878
B8: 0.0175 | C8: 0.065904546 | D8: -1.1612585 | E8: 0.50772363 | F8: 0.1574118 | G8: =C9-C8 -> 0.075099768 | H8: =D9-D8 -> -0.010838121 | I8: =E9-E8 -> -0.013406236 | J8: =F9-F8 -> -0.006704988 | L8: 0.0575 | M8: 1.3017932 | N8: -1.3396174 | O8: 0.28710226 | P8: 0.047070336 | Q8: =M9-M8 -> 0.079736025 | R8: =N9-N8 -> -0.011507209 | S8: =O9-O8 -> -0.014233865 | T8: =P9-P8 -> -0.007118918 | V8: 0.0975 | W8: 2.6146406 | X8: -1.5290827 | Y8: 0.052742789 | Z8: -0.07014209 | AA8: =W9-W8 -> 0.084747935 | AB8: =X9-X8 -> -0.012230509 | AC8: =Y9-Y8 -> -0.015128553 | AD8: =Z9-Z8 -> -0.0075663867
B9: 0.02 | C9: 0.14100431 | D9: -1.1720966 | E9: 0.4943174 | F9: 0.15070681 | G9: =AVERAGE(G2:G8) -> 0.074272608 | H9: =AVERAGE(H2:H8) -> -0.010718749 | I9: =AVERAGE(I2:I8) -> -0.013258577 | J9: =AVERAGE(J2:J8) -> -0.0066311382 | L9: 0.06 | M9: 1.3815292 | N9: -1.3511246 | O9: 0.27286839 | P9: 0.039951418 | Q9: =AVERAGE(Q2:Q8) -> 0.078841884 | R9: =AVERAGE(R2:R8) -> -0.01137817 | S9: =AVERAGE(S2:S8) -> -0.01407425 | T9: =AVERAGE(T2:T8) -> -0.0070390881 | V9: 0.1 | W9: 2.6993885 | X9: -1.5413132 | Y9: 0.037614236 | Z9: -0.077708476 | AA9: =AVERAGE(AA2:AA8) -> 0.083781361 | AB9: =AVERAGE(AB2:AB8) -> -0.012091017 | AC9: =AVERAGE(AC2:AC8) -> -0.014956007 | AD9: =AVERAGE(AD2:AD8) -> -0.0074800899
A10: uh211 | B10: 0.0025 | C10: -0.45208609 | D10: -1.066148 | E10: 0.57688441 | F10: 0.21625175 | G10: =C11-C10 -> 0 | H10: =D11-D10 -> 0.02044333 | I10: =E11-E10 -> -0.023406973 | J10: =F11-F10 -> 0.012647236 | K10: uh211 | L10: 0.0425 | M10: -0.45208609 | N10: -0.72820778 | O10: 0.18995342 | P10: 0.42531799 | Q10: =M11-M10 -> 0 | R10: =N11-N10 -> 0.021914655 | S10: =O11-O10 -> -0.025091594 | T10: =P11-P10 -> 0.013557469 | U10: uh211 | V10: 0.0825 | W10: -0.45208609 | X10: -0.36562385 | Y10: -0.22519381 | Z10: 0.64963 | AA10: =W11-W10 -> 0 | AB10: =X11-X10 -> 0.023536046 | AC10: =Y11-Y10 -> -0.026948036 | AD10: =Z11-Z10 -> 0.014560541
B11: 0.005 | C11: -0.45208609 | D11: -1.0457047 | E11: 0.55347744 | F11: 0.22889899 | G11: =C12-C11 -> 0 | H11: =D12-D11 -> 0.02053121 | I11: =E12-E11 -> -0.023507593 | J11: =F12-F11 -> 0.012701603 | L11: 0.045 | M11: -0.45208609 | N11: -0.70629312 | O11: 0.16486183 | P11: 0.43887546 | Q11: =M12-M11 -> 0 | R11: =N12-N11 -> 0.022011416 | S11: =O12-O11 -> -0.025202381 | T11: =P12-P11 -> 0.01361733 | V11: 0.085 | W11: -0.45208609 | X11: -0.34208781 | Y11: -0.25214185 | Z11: 0.66419054 | AA11: =W12-W11 -> 0 | AB11: =X12-X11 -> 0.023642774 | AC11: =Y12-Y11 -> -0.027070235 | AD11: =Z12-Z11 -> 0.014626568
B12: 0.0075 | C12: -0.45208609 | D12: -1.0251735 | E12: 0.52996984 | F12: 0.24160059 | G12: =C13-C12 -> 0 | H12: =D13-D12 -> 0.020619616 | I12: =E13-E12 -> -0.023608814 | J12: =F13-F12 -> 0.012756295 | L12: 0.0475 | M12: -0.45208609 | N12: -0.68428171 | O12: 0.13965945 | P12: 0.45249279 | Q12: =M13-M12 -> 0 | R12: =N13-N12 -> 0.022108766 | S12: =O13-O12 -> -0.025313844 | T12: =P13-P12 -> 0.013677556 | V12: 0.0875 | W12: -0.45208609 | X12: -0.31844503 | Y12: -0.27921208 | Z12: 0.67881711 | AA12: =W13-W12 -> 0 | AB12: =X13-X12 -> 0.023750164 | AC12: =Y13-Y12 -> -0.027193193 | AD12: =Z13-Z12 -> 0.014693004
B13: 0.01 | C13: -0.45208609 | D13: -1.0045539 | E13: 0.50636103 | F13: 0.25435689 | G13: =C14-C13 -> 0 | H13: =D14-D13 -> 0.020708551 | I13: =E14-E13 -> -0.023710642 | J13: =F14-F13 -> 0.012811315 | L13: 0.05 | M13: -0.45208609 | N13: -0.66217294 | O13: 0.11434561 | P13: 0.46617034 | Q13: =M14-M13 -> 0 | R13: =N14-N13 -> 0.02220671 | S13: =O14-O13 -> -0.025425987 | T13: =P14-P13 -> 0.013738149 | V13: 0.09 | W13: -0.45208609 | X13: -0.29469487 | Y13: -0.30640527 | Z13: 0.69351012 | AA13: =W14-W13 -> 0 | AB13: =X14-X13 -> 0.02385822 | AC13: =Y14-Y13 -> -0.027316915 | AD13: =Z14-Z13 -> 0.014759853
B14: 0.0125 | C14: -0.45208609 | D14: -0.98384531 | E14: 0.48265039 | F14: 0.2671682 | G14: =C15-C14 -> 0 | H14: =D15-D14 -> 0.020798019 | I14: =E15-E14 -> -0.02381308 | J14: =F15-F14 -> 0.012866664 | L14: 0.0525 | M14: -0.45208609 | N14: -0.63996623 | O14: 0.088919618 | P14: 0.47990849 | Q14: =M15-M14 -> 0 | R14: =N15-N14 -> 0.022305253 | S14: =O15-O14 -> -0.025538816 | T14: =P15-P14 -> 0.013799112 | V14: 0.0925 | W14: -0.45208609 | X14: -0.27083665 | Y14: -0.33372219 | Z14: 0.70826997 | AA14: =W15-W14 -> 0 | AB14: =X15-X14 -> 0.023966948 | AC14: =Y15-Y14 -> -0.027441405 | AD14: =Z15-Z14 -> 0.014827118
B15: 0.015 | C15: -0.45208609 | D15: -0.96304729 | E15: 0.45883731 | F15: 0.28003487 | G15: =C16-C15 -> 0 | H15: =D16-D15 -> 0.020888025 | I15: =E16-E15 -> -0.023916133 | J15: =F16-F15 -> 0.012922346 | L15: 0.055 | M15: -0.45208609 | N15: -0.61766098 | O15: 0.063380803 | P15: 0.4937076 | Q15: =M16-M15 -> 0 | R15: =N16-N15 -> 0.022404398 | S15: =O16-O15 -> -0.025652334 | T15: =P16-P15 -> 0.013860448 | V15: 0.095 | W15: -0.45208609 | X15: -0.2468697 | Y15: -0.36116359 | Z15: 0.72309709 | AA15: =W16-W15 -> 0 | AB15: =X16-X15 -> 0.024076353 | AC15: =Y16-Y15 -> -0.02756667 | AD15: =Z16-Z15 -> 0.014894801
B16: 0.0175 | C16: -0.45208609 | D16: -0.94215927 | E16: 0.43492117 | F16: 0.29295721 | G16: =C17-C16 -> 0 | H16: =D17-D16 -> 0.020978571 | I16: =E17-E16 -> -0.024019806 | J16: =F17-F16 -> 0.012978362 | L16: 0.0575 | M16: -0.45208609 | N16: -0.59525658 | O16: 0.037728469 | P16: 0.50756805 | Q16: =M17-M16 -> 0 | R16: =N17-N16 -> 0.022504151 | S16: =O17-O16 -> -0.025766547 | T16: =P17-P16 -> 0.01392216 | V16: 0.0975 | W16: -0.45208609 | X16: -0.22279335 | Y16: -0.38873026 | Z16: 0.73799189 | AA16: =W17-W16 -> 0 | AB16: =X17-X16 -> 0.024186439 | AC16: =Y17-Y16 -> -0.027692715 | AD16: =Z17-Z16 -> 0.014962905
B17: 0.02 | C17: -0.45208609 | D17: -0.9211807 | E17: 0.41090137 | F17: 0.30593557 | G17: =AVERAGE(G10:G16) -> 0 | H17: =AVERAGE(H10:H16) -> 0.020709617 | I17: =AVERAGE(I10:I16) -> -0.023711863 | J17: =AVERAGE(J10:J16) -> 0.012811975 | L17: 0.06 | M17: -0.45208609 | N17: -0.57275243 | O17: 0.011961922 | P17: 0.52149021 | Q17: =AVERAGE(Q10:Q16) -> 0 | R17: =AVERAGE(R10:R16) -> 0.022207907 | S17: =AVERAGE(S10:S16) -> -0.025427358 | T17: =AVERAGE(T10:T16) -> 0.013738889 | V17: 0.1 | W17: -0.45208609 | X17: -0.19860691 | Y17: -0.41642298 | Z17: 0.75295479 | AA17: =AVERAGE(AA10:AA16) -> 0 | AB17: =AVERAGE(AB10:AB16) -> 0.023859564 | AC17: =AVERAGE(AC10:AC16) -> -0.027318453 | AD17: =AVERAGE(AD10:AD16) -> 0.014760684
A18: uh222 | B18: 0.0025 | C18: -0.45208609 | D18: -1.0670389 | E18: 0.60019136 | F18: 0.19122872 | G18: =C19-C18 -> 0 | H18: =D19-D18 -> 0.019546724 | I18: =E19-E18 -> 0 | J18: =F19-F18 -> -0.01248199 | K18: uh222 | L18: 0.0425 | M18: -0.45208609 | N18: -0.74413904 | O18: 0.60019136 | P18: -0.014966095 | Q18: =M19-M18 -> 0 | R18: =N19-N18 -> 0.020924726 | S18: =O19-O18 -> 0 | T18: =P19-P18 -> -0.013361943 | U18: uh222 | V18: 0.0825 | W18: -0.45208609 | X18: -0.39811416 | Y18: 0.60019136 | Z18: -0.23592788 | AA18: =W19-W18 -> 0 | AB18: =X19-X18 -> 0.022449738 | AC18: =Y19-Y18 -> 0 | AD18: =Z19-Z18 -> -0.014335773
B19: 0.005 | C19: -0.45208609 | D19: -1.0474922 | E19: 0.60019136 | F19: 0.17874673 | G19: =C20-C19 -> 0 | H19: =D20-D19 -> 0.019628894 | I19: =E20-E19 -> 0 | J19: =F20-F19 -> -0.012534461 | L19: 0.045 | M19: -0.45208609 | N19: -0.72321431 | O19: 0.60019136 | P19: -0.028328038 | Q19: =M20-M19 -> 0 | R19: =N20-N19 -> 0.021015532 | S19: =O20-O19 -> 0 | T19: =P20-P19 -> -0.013419929 | V19: 0.085 | W19: -0.45208609 | X19: -0.37566442 | Y19: 0.60019136 | Z19: -0.25026365 | AA19: =W20-W19 -> 0 | AB19: =X20-X19 -> 0.022550391 | AC19: =Y20-Y19 -> 0 | AD19: =Z20-Z19 -> -0.014400047
B20: 0.0075 | C20: -0.45208609 | D20: -1.0278633 | E20: 0.60019136 | F20: 0.16621227 | G20: =C21-C20 -> 0 | H20: =D21-D20 -> 0.019711572 | I20: =E21-E20 -> 0 | J20: =F21-F20 -> -0.012587257 | L20: 0.0475 | M20: -0.45208609 | N20: -0.70219878 | O20: 0.60019136 | P20: -0.041747967 | Q20: =M21-M20 -> 0 | R20: =N21-N20 -> 0.021106916 | S20: =O21-O20 -> 0 | T20: =P21-P20 -> -0.013478284 | V20: 0.0875 | W20: -0.45208609 | X20: -0.35311403 | Y20: 0.60019136 | Z20: -0.2646637 | AA20: =W21-W20 -> 0 | AB20: =X21-X20 -> 0.022651705 | AC20: =Y21-Y20 -> 0 | AD20: =Z21-Z20 -> -0.014464744
B21: 0.01 | C21: -0.45208609 | D21: -1.0081517 | E21: 0.60019136 | F21: 0.15362501 | G21: =C22-C21 -> 0 | H21: =D22-D21 -> 0.019794761 | I21: =E22-E21 -> 0 | J21: =F22-F21 -> -0.012640379 | L21: 0.05 | M21: -0.45208609 | N21: -0.68109187 | O21: 0.60019136 | P21: -0.055226252 | Q21: =M22-M21 -> 0 | R21: =N22-N21 -> 0.021198882 | S21: =O22-O21 -> 0 | T21: =P22-P21 -> -0.013537012 | V21: 0.09 | W21: -0.45208609 | X21: -0.33046233 | Y21: 0.60019136 | Z21: -0.27912844 | AA21: =W22-W21 -> 0 | AB21: =X22-X21 -> 0.022753685 | AC21: =Y22-Y21 -> 0 | AD21: =Z22-Z21 -> -0.014529865
B22: 0.0125 | C22: -0.45208609 | D22: -0.98835698 | E22: 0.60019136 | F22: 0.14098463 | G22: =C23-C22 -> 0 | H22: =D23-D22 -> 0.019878466 | I22: =E23-E22 -> 0 | J22: =F23-F22 -> -0.012693831 | L22: 0.0525 | M22: -0.45208609 | N22: -0.65989299 | O22: 0.60019136 | P22: -0.068763263 | Q22: =M23-M22 -> 0 | R22: =N23-N22 -> 0.021291436 | S22: =O23-O22 -> 0 | T22: =P23-P22 -> -0.013596114 | V22: 0.0925 | W22: -0.45208609 | X22: -0.30770864 | Y22: 0.60019136 | Z22: -0.29365831 | AA22: =W23-W22 -> 0 | AB22: =X23-X22 -> 0.022856336 | AC22: =Y23-Y22 -> 0 | AD22: =Z23-Z22 -> -0.014595415
B23: 0.015 | C23: -0.45208609 | D23: -0.96847852 | E23: 0.60019136 | F23: 0.1282908 | G23: =C24-C23 -> 0 | H23: =D24-D23 -> 0.019962692 | I23: =E24-E23 -> 0 | J23: =F24-F23 -> -0.012747615 | L23: 0.055 | M23: -0.45208609 | N23: -0.63860155 | O23: 0.60019136 | P23: -0.082359377 | Q23: =M24-M23 -> 0 | R23: =N24-N23 -> 0.021384583 | S23: =O24-O23 -> 0 | T23: =P24-P23 -> -0.013655595 | V23: 0.095 | W23: -0.45208609 | X23: -0.28485231 | Y23: 0.60019136 | Z23: -0.30825372 | AA23: =W24-W23 -> 0 | AB23: =X24-X23 -> 0.022959665 | AC23: =Y24-Y23 -> 0 | AD23: =Z24-Z23 -> -0.014661398
B24: 0.0175 | C24: -0.45208609 | D24: -0.94851582 | E24: 0.60019136 | F24: 0.11554319 | G24: =C25-C24 -> 0 | H24: =D25-D24 -> 0.020047441 | I24: =E25-E24 -> 0 | J24: =F25-F24 -> -0.012801734 | L24: 0.0575 | M24: -0.45208609 | N24: -0.61721697 | O24: 0.60019136 | P24: -0.096014972 | Q24: =M25-M24 -> 0 | R24: =N25-N24 -> 0.021478327 | S24: =O25-O24 -> 0 | T24: =P25-P24 -> -0.013715457 | V24: 0.0975 | W24: -0.45208609 | X24: -0.26189264 | Y24: 0.60019136 | Z24: -0.32291512 | AA24: =W25-W24 -> 0 | AB24: =X25-X24 -> 0.023063677 | AC24: =Y25-Y24 -> 0 | AD24: =Z25-Z24 -> -0.014727817
B25: 0.02 | C25: -0.45208609 | D25: -0.92846838 | E25: 0.60019136 | F25: 0.10274145 | G25: =AVERAGE(G18:G24) -> 0 | H25: =AVERAGE(H18:H24) -> 0.019795793 | I25: =AVERAGE(I18:I24) -> 0 | J25: =AVERAGE(J18:J24) -> -0.012641038 | L25: 0.06 | M25: -0.45208609 | N25: -0.59573864 | O25: 0.60019136 | P25: -0.10973043 | Q25: =AVERAGE(Q18:Q24) -> 0 | R25: =AVERAGE(R18:R24) -> 0.021200057 | S25: =AVERAGE(S18:S24) -> 0 | T25: =AVERAGE(T18:T24) -> -0.013537762 | V25: 0.1 | W25: -0.45208609 | X25: -0.23882896 | Y25: 0.60019136 | Z25: -0.33764294 | AA25: =AVERAGE(AA18:AA24) -> 0 | AB25: =AVERAGE(AB18:AB24) -> 0.022755028 | AC25: =AVERAGE(AC18:AC24) -> 0 | AD25: =AVERAGE(AD18:AD24) -> -0.014530723
A26: uc122 | B26: 0.0025 | C26: -0.43169107 | D26: -1.0894473 | E26: 0.5965506 | F26: 0.20183767 | G26: =C27-C26 -> 0.02050335 | H26: =D27-D26 -> -0.0029589678 | I26: =E27-E26 -> -0.003660101 | J26: =F27-F26 -> -0.0018305611 | K26: uc122 | L26: 0.0425 | M26: -0.090042506 | N26: -1.1387528 | O26: 0.53556211 | P26: 0.17133492 | Q26: =M27-M26 -> 0.022357592 | R26: =N27-N26 -> -0.0032265651 | S26: =O27-O26 -> -0.0039911061 | T26: =P27-P26 -> -0.0019961098 | U26: uc122 | V26: 0.0825 | W26: 0.28313452 | X26: -1.1926083 | Y26: 0.4689454 | Z26: 0.13801727 | AA26: =W27-W26 -> 0.024467514 | AB26: =X27-X26 -> -0.0035310613 | AC26: =Y27-Y26 -> -0.0043677533 | AD26: =Z27-Z26 -> -0.0021844859
B27: 0.005 | C27: -0.41118772 | D27: -1.0924063 | E27: 0.59289049 | F27: 0.20000711 | G27: =C28-C27 -> 0.020612523 | H27: =D28-D27 -> -0.0029747233 | I27: =E28-E27 -> -0.0036795899 | J27: =F28-F27 -> -0.0018403082 | L27: 0.045 | M27: -0.067684915 | N27: -1.1419793 | O27: 0.531571 | P27: 0.16933881 | Q27: =M28-M27 -> 0.022481525 | R27: =N28-N27 -> -0.0032444507 | S27: =O28-O27 -> -0.0040132297 | T27: =P28-P27 -> -0.0020071747 | V27: 0.085 | W27: 0.30760203 | X27: -1.1961394 | Y27: 0.46457765 | Z27: 0.13583279 | AA27: =W28-W27 -> 0.024608908 | AB27: =X28-X27 -> -0.0035514668 | AC27: =Y28-Y27 -> -0.0043929939 | AD27: =Z28-Z27 -> -0.0021971098
B28: 0.0075 | C28: -0.39057519 | D28: -1.095381 | E28: 0.5892109 | F28: 0.1981668 | G28: =C29-C28 -> 0.02072255 | H28: =D29-D28 -> -0.002990602 | I28: =E29-E28 -> -0.0036992311 | J28: =F29-F28 -> -0.0018501316 | L28: 0.0475 | M28: -0.04520339 | N28: -1.1452238 | O28: 0.52755777 | P28: 0.16733164 | Q28: =M29-M28 -> 0.022606464 | R28: =N29-N28 -> -0.0032624815 | S28: =O29-O28 -> -0.004035533 | T28: =P29-P28 -> -0.0020183294 | V28: 0.0875 | W28: 0.33221094 | X28: -1.1996908 | Y28: 0.46018466 | Z28: 0.13363568 | AA28: =W29-W28 -> 0.024751497 | AB28: =X29-X28 -> -0.0035720448 | AC28: =Y29-Y28 -> -0.0044184479 | AD28: =Z29-Z28 -> -0.0022098403
B29: 0.01 | C29: -0.36985264 | D29: -1.0983716 | E29: 0.58551167 | F29: 0.19631667 | G29: =C30-C29 -> 0.020833439 | H29: =D30-D29 -> -0.0030066051 | I29: =E30-E29 -> -0.0037190261 | J29: =F30-F29 -> -0.0018600318 | L29: 0.05 | M29: -0.022596926 | N29: -1.1484863 | O29: 0.52352224 | P29: 0.16531331 | Q29: =M30-M29 -> 0.022732421 | R29: =N30-N29 -> -0.0032806591 | S29: =O30-O29 -> -0.0040580178 | T29: =P30-P29 -> -0.0020295749 | V29: 0.09 | W29: 0.35696244 | X29: -1.2032629 | Y29: 0.45576621 | Z29: 0.13142584 | AA29: =W30-W29 -> 0.024895294 | AB29: =X30-X29 -> -0.003592797 | AC29: =Y30-Y29 -> -0.0044441173 | AD29: =Z30-Z29 -> -0.0022226786
B30: 0.0125 | C30: -0.3490192 | D30: -1.1013782 | E30: 0.58179265 | F30: 0.19445664 | G30: =C31-C30 -> 0.020945199 | H30: =D31-D30 -> -0.0030227338 | I30: =E31-E30 -> -0.0037389766 | J30: =F31-F30 -> -0.0018700099 | L30: 0.0525 | M30: 0.00013549485 | N30: -1.1517669 | O30: 0.51946422 | P30: 0.16328373 | Q30: =M31-M30 -> 0.022859405 | R30: =N31-N30 -> -0.003298985 | S30: =O31-O30 -> -0.004080686 | T30: =P31-P30 -> -0.0020409122 | V30: 0.0925 | W30: 0.38185773 | X30: -1.2068557 | Y30: 0.45132209 | Z30: 0.12920316 | AA30: =W31-W30 -> 0.025040312 | AB30: =X31-X30 -> -0.0036137254 | AC30: =Y31-Y30 -> -0.0044700048 | AD30: =Z31-Z30 -> -0.0022356259
B31: 0.015 | C31: -0.32807401 | D31: -1.104401 | E31: 0.57805367 | F31: 0.19258663 | G31: =C32-C31 -> 0.021057838 | H31: =D32-D31 -> -0.0030389895 | I31: =E32-E31 -> -0.0037590841 | J31: =F32-F31 -> -0.0018800664 | L31: 0.055 | M31: 0.0229949 | N31: -1.1550659 | O31: 0.51538354 | P31: 0.16124282 | Q31: =M32-M31 -> 0.022987428 | R31: =N32-N31 -> -0.0033174608 | S31: =O32-O31 -> -0.0041035398 | T31: =P32-P31 -> -0.0020523423 | V31: 0.095 | W31: 0.40689804 | X31: -1.2104694 | Y31: 0.44685209 | Z31: 0.12696753 | AA31: =W32-W31 -> 0.025186564 | AB31: =X32-X31 -> -0.003634832 | AC31: =Y32-Y31 -> -0.0044961126 | AD31: =Z32-Z31 -> -0.0022486835
B32: 0.0175 | C32: -0.30701617 | D32: -1.1074399 | E32: 0.57429459 | F32: 0.19070656 | G32: =C33-C32 -> 0.021171366 | H32: =D33-D32 -> -0.0030553734 | I32: =E33-E32 -> -0.0037793502 | J32: =F33-F32 -> -0.0018902023 | L32: 0.0575 | M32: 0.045982328 | N32: -1.1583834 | O32: 0.51128 | P32: 0.15919048 | Q32: =M33-M32 -> 0.023116501 | R32: =N33-N32 -> -0.0033360882 | S32: =O33-O32 -> -0.0041265809 | T32: =P33-P32 -> -0.0020638661 | V32: 0.0975 | W32: 0.43208461 | X32: -1.2141042 | Y32: 0.44235597 | Z32: 0.12471885 | AA32: =W33-W32 -> 0.025334064 | AB32: =X33-X32 -> -0.0036561186 | AC32: =Y33-Y32 -> -0.0045224432 | AD32: =Z33-Z32 -> -0.0022618524
B33: 0.02 | C33: -0.2858448 | D33: -1.1104953 | E33: 0.57051524 | F33: 0.18881636 | G33: =AVERAGE(G26:G32) -> 0.020835181 | H33: =AVERAGE(H26:H32) -> -0.0030068564 | I33: =AVERAGE(I26:I32) -> -0.003719337 | J33: =AVERAGE(J26:J32) -> -0.0018601873 | L33: 0.06 | M33: 0.069098829 | N33: -1.1617195 | O33: 0.50715342 | P33: 0.15712661 | Q33: =AVERAGE(Q26:Q32) -> 0.022734476 | R33: =AVERAGE(R26:R32) -> -0.0032809558 | S33: =AVERAGE(S26:S32) -> -0.0040583847 | T33: =AVERAGE(T26:T32) -> -0.0020297585 | V33: 0.1 | W33: 0.45741867 | X33: -1.2177604 | Y33: 0.43783353 | Z33: 0.122457 | AA33: =AVERAGE(AA26:AA32) -> 0.024897736 | AB33: =AVERAGE(AB26:AB32) -> -0.0035931494 | AC33: =AVERAGE(AC26:AC32) -> -0.0044445533 | AD33: =AVERAGE(AD26:AD32) -> -0.0022228966
A34: uc211 | B34: 0.0025 | C34: -0.45208609 | D34: -1.0745339 | E34: 0.58648595 | F34: 0.21106385 | G34: =C35-C34 -> 0 | H34: =D35-D34 -> 0.012029881 | I34: =E35-E34 -> -0.013773837 | J34: =F35-F34 -> 0.0074422683 | K34: uc211 | L34: 0.0425 | M34: -0.45208609 | N34: -0.87458047 | O34: 0.35754557 | P34: 0.33476473 | Q34: =M35-M34 -> 0 | R34: =N35-N34 -> 0.013047687 | S34: =O35-O34 -> -0.014939193 | T34: =P35-P34 -> 0.0080719325 | U34: uc211 | V34: 0.0825 | W34: -0.45208609 | X34: -0.65740303 | Y34: 0.1088842 | Z34: 0.46912125 | AA34: =W35-W34 -> 0 | AB34: =X35-X34 -> 0.014194173 | AC34: =Y35-Y34 -> -0.016251883 | AD34: =Z35-Z34 -> 0.0087812044
B35: 0.005 | C35: -0.45208609 | D35: -1.062504 | E35: 0.57271211 | F35: 0.21850612 | G35: =C36-C35 -> 0 | H35: =D36-D35 -> 0.012090078 | I35: =E36-E35 -> -0.013842761 | J35: =F36-F35 -> 0.0074795093 | L35: 0.045 | M35: -0.45208609 | N35: -0.86153279 | O35: 0.34260638 | P35: 0.34283667 | Q35: =M36-M35 -> 0 | R35: =N36-N35 -> 0.013115369 | S35: =O36-O35 -> -0.015016687 | T35: =P36-P35 -> 0.0081138041 | V35: 0.085 | W35: -0.45208609 | X35: -0.64320885 | Y35: 0.092632316 | Z35: 0.47790245 | AA35: =W36-W35 -> 0 | AB35: =X36-X35 -> 0.014270569 | AC35: =Y36-Y35 -> -0.016339354 | AD35: =Z36-Z35 -> 0.0088284667
B36: 0.0075 | C36: -0.45208609 | D36: -1.0504139 | E36: 0.55886935 | F36: 0.22598563 | G36: =C37-C36 -> 0 | H36: =D37-D36 -> 0.012150712 | I36: =E37-E36 -> -0.013912184 | J36: =F37-F36 -> 0.0075170199 | L36: 0.0475 | M36: -0.45208609 | N36: -0.84841742 | O36: 0.32758969 | P36: 0.35095047 | Q36: =M37-M36 -> 0 | R36: =N37-N36 -> 0.013183558 | S36: =O37-O36 -> -0.015094761 | T36: =P37-P36 -> 0.0081559888 | V36: 0.0875 | W36: -0.45208609 | X36: -0.62893828 | Y36: 0.076292962 | Z36: 0.48673092 | AA36: =W37-W36 -> 0 | AB36: =X37-X36 -> 0.014347556 | AC36: =Y37-Y36 -> -0.016427502 | AD36: =Z37-Z36 -> 0.0088760944
B37: 0.01 | C37: -0.45208609 | D37: -1.0382632 | E37: 0.54495717 | F37: 0.23350265 | G37: =C38-C37 -> 0 | H37: =D38-D37 -> 0.012211785 | I37: =E38-E37 -> -0.013982111 | J37: =F38-F37 -> 0.0075548027 | L37: 0.05 | M37: -0.45208609 | N37: -0.83523386 | O37: 0.31249493 | P37: 0.35910646 | Q37: =M38-M37 -> 0 | R37: =N38-N37 -> 0.013252258 | S37: =O38-O37 -> -0.01517342 | T37: =P38-P37 -> 0.0081984898 | V37: 0.09 | W37: -0.45208609 | X37: -0.61459073 | Y37: 0.05986546 | Z37: 0.49560701 | AA37: =W38-W37 -> 0 | AB37: =X38-X37 -> 0.014425139 | AC37: =Y38-Y37 -> -0.016516332 | AD37: =Z38-Z37 -> 0.0089240912
B38: 0.0125 | C38: -0.45208609 | D38: -1.0260514 | E38: 0.53097506 | F38: 0.24105746 | G38: =C39-C38 -> 0 | H38: =D39-D38 -> 0.012273302 | I38: =E39-E38 -> -0.014052546 | J38: =F39-F38 -> 0.0075928601 | L38: 0.0525 | M38: -0.45208609 | N38: -0.8219816 | O38: 0.29732151 | P38: 0.36730495 | Q38: =M39-M38 -> 0 | R38: =N39-N38 -> 0.013321473 | S38: =O39-O38 -> -0.01525267 | T38: =P39-P38 -> 0.00824131 | V38: 0.0925 | W38: -0.45208609 | X38: -0.60016559 | Y38: 0.043349127 | Z38: 0.5045311 | AA38: =W39-W38 -> 0 | AB38: =X39-X38 -> 0.014503325 | AC38: =Y39-Y38 -> -0.016605853 | AD38: =Z39-Z38 -> 0.0089724608
B39: 0.015 | C39: -0.45208609 | D39: -1.0137781 | E39: 0.51692251 | F39: 0.24865032 | G39: =C40-C39 -> 0 | H39: =D40-D39 -> 0.012335267 | I39: =E40-E39 -> -0.014123494 | J39: =F40-F39 -> 0.0076311947 | L39: 0.055 | M39: -0.45208609 | N39: -0.80866013 | O39: 0.28206884 | P39: 0.37554626 | Q39: =M40-M39 -> 0 | R39: =N40-N39 -> 0.01339121 | S39: =O40-O39 -> -0.015332516 | T39: =P40-P39 -> 0.0082844525 | V39: 0.095 | W39: -0.45208609 | X39: -0.58566226 | Y39: 0.026743275 | Z39: 0.51350356 | AA39: =W40-W39 -> 0 | AB39: =X40-X39 -> 0.014582119 | AC39: =Y40-Y39 -> -0.016696069 | AD39: =Z40-Z39 -> 0.0090212067
B40: 0.0175 | C40: -0.45208609 | D40: -1.0014429 | E40: 0.50279902 | F40: 0.25628151 | G40: =C41-C40 -> 0 | H40: =D41-D40 -> 0.012397684 | I40: =E41-E40 -> -0.01419496 | J40: =F41-F40 -> 0.0076698091 | L40: 0.0575 | M40: -0.45208609 | N40: -0.79526892 | O40: 0.26673633 | P40: 0.38383071 | Q40: =M41-M40 -> 0 | R40: =N41-N40 -> 0.013461473 | S40: =O41-O40 -> -0.015412965 | T40: =P41-P40 -> 0.0083279205 | V40: 0.0975 | W40: -0.45208609 | X40: -0.57108014 | Y40: 0.010047205 | Z40: 0.52252477 | AA40: =W41-W40 -> 0 | AB40: =X41-X40 -> 0.014661528 | AC40: =Y41-Y40 -> -0.01678699 | AD40: =Z41-Z40 -> 0.0090703327
...

Sheet Todo en 0 Ratio Max-Final th1
C1: th1
B2: uh122 | C2: MAX | D2: FINAL | E2: Ratio
B3: 0.0025 | C3: 383.85132 | D3: 383.54122 | E3: =C3/D3 -> 1.0008085 | G3: =D4-D3 -> 0.28279065
B4: 0.005 | C4: 384.44317 | D4: 383.82401 | E4: =C4/D4 -> 1.0016131 | G4: =D5-D4 -> 0.2838351
B5: 0.0075 | C5: 385.03502 | D5: 384.10785 | E5: =C5/D5 -> 1.0024138 | G5: =D6-D5 -> 0.28488463
B6: 0.01 | C6: 385.62687 | D6: 384.39273 | E6: =C6/D6 -> 1.0032106 | G6: =D7-D6 -> 0.28593927
B7: 0.0125 | C7: 386.21872 | D7: 384.67867 | E7: =C7/D7 -> 1.0040035 | G7: =D8-D7 -> 0.28699904
B8: 0.015 | C8: 386.81058 | D8: 384.96567 | E8: =C8/D8 -> 1.0047924 | G8: =D9-D8 -> 0.28806398
B9: 0.0175 | C9: 387.40243 | D9: 385.25373 | E9: =C9/D9 -> 1.0055773 | G9: =D10-D9 -> 0.28913411
B10: 0.02 | C10: 387.99428 | D10: 385.54287 | E10: =C10/D10 -> 1.0063583 | G10: =D11-D10 -> 0.29020945
B11: 0.0225 | C11: 388.58613 | D11: 385.83308 | E11: =C11/D11 -> 1.0071353 | G11: =D12-D11 -> 0.29129003
B12: 0.025 | C12: 389.17798 | D12: 386.12437 | E12: =C12/D12 -> 1.0079084 | G12: =D13-D12 -> 0.29237588
B13: 0.0275 | C13: 389.76983 | D13: 386.41674 | E13: =C13/D13 -> 1.0086774 | G13: =D14-D13 -> 0.29346703
B14: 0.03 | C14: 390.36168 | D14: 386.71021 | E14: =C14/D14 -> 1.0094424 | G14: =D15-D14 -> 0.2945635
... B41: 0.0975 | C41: 406.34167 | D41: 395.06637 | E41: =C41/D41 -> 1.0285403 | G41: =D42-D41 -> 0.32627955
B42: 0.1 | C42: 406.93352 | D42: 395.39265 | E42: =C42/D42 -> 1.0291884

Sheet Nominales el resto en 0
G2: SALIDA | H2: Kp | I2: Tp | J2: Td | K2: VALOR | L2: #
A3: 0.825 | B3: 0.033810479 | C3: -0.011812028 | D3: -0.0044916172 | E3: -0.002046103 | G3: th1 | H3: -123.12201 | I3: 2.0882859 | J3: 1.506 | K3: 0.825 | L3: 1
A4: 0.85 | B4: 0.033810479 | C4: -0.011812028 | D4: -0.0044916172 | E4: -0.002046103 | G4: th2 | H4: -17.150327 | I4: 2.7807014 | J4: 4.056 | K4: 0.825 | L4: 2
A5: 0.875 | B5: 0.033810479 | C5: -0.011812028 | D5: -0.0044916172 | E5: -0.002046103 | G5: tc1 | H5: -30.127888 | I5: 2.3021797 | J5: 3.769 | K5: 0.825 | L5: 3
A6: 0.9 | B6: 0.033810479 | C6: -0.011812028 | D6: -0.0044916172 | E6: -0.002046103 | G6: tc2 | H6: -8.5948735 | I6: 2.738449 | J6: 3.708 | K6: 0.825 | L6: 4
A7: 0.925 | B7: 0.033810479 | C7: -0.011812028 | D7: -0.0044916172 | E7: -0.002046103 | G7: th1 | H7: -123.15207 | I7: 2.2769908 | J7: 1.449 | K7: 0.85 | L7: 5
A8: 0.95 | B8: 0.033810479 | C8: -0.011812028 | D8: -0.0044916172 | E8: -0.002046103 | G8: th2 | H8: -17.135473 | I8: 2.4874536 | J8: 4.581 | K8: 0.85 | L8: 6
A9: 0.975 | B9: 0.033810479 | C9: -0.011812028 | D9: -0.0044916172 | E9: -0.002046103 | G9: tc1 | H9: -30.09107 | I9: 1.8248896 | J9: 4.55 | K9: 0.85 | L9: 7
A10: 1 | B10: 0.033810479 | C10: -0.011812028 | D10: -0.0044916172 | E10: -0.002046103 | G10: tc2 | H10: -8.5826899 | I10: 2.27419 | J10: 4.452 | K10: 0.85 | L10: 8
A11: 1.025 | B11: 0.033810479 | C11: -0.011812028 | D11: -0.0044916172 | E11: -0.002046103 | G11: th1 | H11: -123.15216 | I11: 2.2769907 | J11: 1.449 | K11: 0.875 | L11: 9
A12: 1.05 | B12: 0.033810479 | C12: -0.011812028 | D12: -0.0044916172 | E12: -0.002046103 | G12: th2 | H12: -17.136399 | I12: 2.4874184 | J12: 4.581 | K12: 0.875 | L12: 10
A13: 1.075 | B13: 0.033810479 | C13: -0.011812028 | D13: -0.0044916172 | E13: -0.002046103 | G13: tc1 | H13: -30.091892 | I13: 1.8248835 | J13: 4.55 | K13: 0.875 | L13: 11
A14: 1.1 | B14: 0.033810479 | C14: -0.011812028 | D14: -0.0044916172 | E14: -0.002046103 | G14: tc2 | H14: -8.5832923 | I14: 2.2741669 | J14: 4.452 | K14: 0.875 | L14: 12
... A17: 1.175 | B17: 0.033810479 | C17: -0.011812028 | D17: -0.0044916172 | E17: -0.002046103 | G17: tc1 | H17: -30.12812 | I17: 2.3021767 | J17: 3.769 | K17: 0.9 | L17: 15
G18: tc2 | H18: -8.5949814 | I18: 2.7384413 | J18: 3.708 | K18: 0.9 | L18: 16
G19: th1 | H19: -123.15216 | I19: 2.2769907 | J19: 1.449 | K19: 0.925 | L19: 17
G20: th2 | H20: -17.136399 | I20: 2.4874184 | J20: 4.581 | K20: 0.925 | L20: 18
G21: tc1 | H21: -30.091892 | I21: 1.8248835 | J21: 4.55 | K21: 0.925 | L21: 19
G22: tc2 | H22: -8.5832923 | I22: 2.2741669 | J22: 4.452 | K22: 0.925 | L22: 20
G23: th1 | H23: -123.15194 | I23: 2.2770025 | J23: 1.449 | K23: 0.95 | L23: 21
G24: th2 | H24: -17.135832 | I24: 2.4879727 | J24: 4.581 | K24: 0.95 | L24: 22
G25: tc1 | H25: -30.090773 | I25: 1.825524 | J25: 4.549 | K25: 0.95 | L25: 23
G26: tc2 | H26: -8.582907 | I26: 2.2761353 | J26: 4.451 | K26: 0.95 | L26: 24
G27: th1 | H27: -123.12192 | I27: 2.088286 | J27: 1.506 | K27: 0.975 | L27: 25
G28: th2 | H28: -17.149401 | I28: 2.7807267 | J28: 4.056 | K28: 0.975 | L28: 26
G29: tc1 | H29: -30.127066 | I29: 2.3021898 | J29: 3.769 | K29: 0.975 | L29: 27
... G62: tc2 | H62: -8.5948735 | I62: 2.738449 | J62: 3.708 | K62: 1.175 | L62: 60

Sheet Variar Nominales h112
A1: uh112 | B1: Parameter Array (tiempo muerto) | J1: Sin Tiempo Muerto | Q1: error final vs setpoint (en % de sp)
B2: n | C2: Valor | D2: Kp | E2: Tp | F2: Td | G2: % | H2: Salida | J2: n | K2: Valor | L2: Kp | M2: Tp | N2: % | O2: Salida | Q2: n | R2: Valor | S2: th1 | T2: th2 | U2: tc1 | V2: tc2
B3: 1 | C3: 0.75 | D3: 114.68859 | E3: 0.16704439 | F3: 0.568 | G3: -13.856643 | H3: th1 | J3: 1 | K3: 0.75 | L3: 117.67137 | M3: 9.504529e-10 | N3: -11.770775 | O3: th1 | Q3: 1 | R3: 0.75 | S3: -0.12207433 | T3: 0.010758239 | U3: 0.023849434 | V3: 0.011260447 | X3: =S4-S3 -> 0.011094919 | Y3: =T4-T3 -> -0.0016064124 | Z3: =U4-U3 -> -0.0020171412 | AA3: =V4-V3 -> -0.00094707817
B4: 2 | C4: 0.75 | D4: -17.273844 | E4: 2.8004615 | F4: 1.462 | G4: 91.910572 | H4: th2 | J4: 2 | K4: 0.75 | L4: -17.393538 | M4: 4.3928006 | N4: 82.781006 | O4: th2 | Q4: 2 | R4: 0.775 | S4: -0.11097941 | T4: 0.0091518265 | U4: 0.021832293 | V4: 0.010313369 | X4: =S5-S4 -> 0.011100751 | Y4: =T5-T4 -> -0.0016072568 | Z4: =U5-U4 -> -0.0020182015 | AA4: =V5-V4 -> -0.000947576
B5: 3 | C5: 0.75 | D5: -30.314891 | E5: 2.1460236 | F5: 1.475 | G5: 93.031877 | H5: tc1 | J5: 3 | K5: 0.75 | L5: -30.529741 | M5: 3.7769874 | N5: 82.114205 | O5: tc1 | Q5: 3 | R5: 0.8 | S5: -0.099878663 | T5: 0.0075445697 | U5: 0.019814091 | V5: 0.0093657932 | X5: =S6-S5 -> 0.011106885 | Y5: =T6-T5 -> -0.0016081448 | Z5: =U6-U5 -> -0.0020193166 | AA5: =V6-V5 -> -0.00094809956
B6: 4 | C6: 0.75 | D6: -8.6482831 | E6: 2.4849249 | F6: 1.409 | G6: 92.529754 | H6: tc2 | J6: 4 | K6: 0.75 | L6: -8.7069252 | M6: 4.0338131 | N6: 82.911675 | O6: tc2 | Q6: 4 | R6: 0.825 | S6: -0.088771778 | T6: 0.0059364249 | U6: 0.017794775 | V6: 0.0084176936 | X6: =S7-S6 -> 0.011113023 | Y6: =T7-T6 -> -0.0016090335 | Z6: =U7-U6 -> -0.0020204325 | AA6: =V7-V6 -> -0.00094862351
B7: 5 | C7: 0.75 | D7: -123.86651 | E7: 0.794457 | F7: 1.243 | G7: 98.89418 | H7: th1 - alt | J7: 5 | K7: 0.775 | L7: 117.67083 | M7: 4.7525774e-10 | N7: -27.36343 | O7: th1 | Q7: 5 | R7: 0.85 | S7: -0.077658755 | T7: 0.0043273914 | U7: 0.015774342 | V7: 0.0074690701 | X7: =S8-S7 -> 0.011119165 | Y7: =T8-T7 -> -0.0016099229 | Z7: =U8-U7 -> -0.0020215493 | AA7: =V8-V7 -> -0.00094914783
B8: 6 | C8: 0.775 | D8: 114.72968 | E8: 0.16085217 | F8: 0.076 | G8: -27.922964 | H8: th1 | J8: 6 | K8: 0.775 | L8: -17.397706 | M8: 4.3921953 | N8: 81.040486 | O8: th2 | Q8: 6 | R8: 0.875 | S8: -0.06653959 | T8: 0.0027174685 | U8: 0.013752793 | V8: 0.0065199223 | X8: =S9-S8 -> 0.011125312 | Y8: =T9-T8 -> -0.0016108129 | Z8: =U9-U8 -> -0.0020226668 | AA8: =V9-V8 -> -0.00094967254
B9: 7 | C9: 0.775 | D9: -17.278011 | E9: 2.8002506 | F9: 1.461 | G9: 91.09277 | H9: th2 | J9: 7 | K9: 0.775 | L9: -30.532992 | M9: 3.7767751 | N9: 80.158519 | O9: tc1 | Q9: 7 | R9: 0.9 | S9: -0.055414278 | T9: 0.0011066556 | U9: 0.011730126 | V9: 0.0055702497 | X9: =S10-S9 -> 0.011131463 | Y9: =T10-T9 -> -0.0016117035 | Z9: =U10-U9 -> -0.0020237852 | AA9: =V10-V9 -> -0.00095019762
B10: 8 | C10: 0.775 | D10: -30.318138 | E10: 2.145952 | F10: 1.475 | G10: 92.270089 | H10: tc1 | J10: 8 | K10: 0.775 | L10: -8.708673 | M10: 4.0333564 | N10: 81.094465 | O10: tc2 | Q10: 8 | R10: 0.925 | S10: -0.044282814 | T10: -0.00050504793 | U10: 0.0097063408 | V10: 0.0046200521 | X10: =S11-S10 -> 0.011137918 | Y10: =T11-T10 -> -0.001612638 | Z10: =U11-U10 -> -0.0020249586 | AA10: =V11-V10 -> -0.00095074856
B11: 9 | C11: 0.775 | D11: -8.6500293 | E11: 2.4847578 | F11: 1.408 | G11: 91.735484 | H11: tc2 | J11: 9 | K11: 0.8 | L11: 117.67083 | M11: 4.7525774e-10 | N11: -27.36343 | O11: th1 | Q11: 9 | R11: 0.95 | S11: -0.033144897 | T11: -0.0021176859 | U11: 0.0076813822 | V11: 0.0036693035 | X11: =S12-S11 -> 0.01114378 | Y11: =T12-T11 -> -0.0016134868 | Z11: =U12-U11 -> -0.0020260244 | AA11: =V12-V11 -> -0.00095124896
B12: 10 | C12: 0.775 | D12: -123.86706 | E12: 0.7944565 | F12: 1.243 | G12: 98.74059 | H12: th1 - alt | J12: 10 | K12: 0.8 | L12: -17.397706 | M12: 4.3921953 | N12: 81.040486 | O12: th2 | Q12: 10 | R12: 0.975 | S12: -0.022001117 | T12: -0.0037311727 | U12: 0.0056553578 | V12: 0.0027180546 | X12: =S13-S12 -> 0.011149944 | Y12: =T13-T12 -> -0.0016143793 | Z12: =U13-U12 -> -0.0020271452 | AA12: =V13-V12 -> -0.00095177519
B13: 11 | C13: 0.8 | D13: 114.72953 | E13: 0.16101794 | F13: 0.078 | G13: -27.924458 | H13: th1 | J13: 11 | K13: 0.8 | L13: -30.532992 | M13: 3.7767751 | N13: 80.158519 | O13: tc1 | Q13: 11 | R13: 1 | S13: -0.010851173 | T13: -0.005345552 | U13: 0.0036282127 | V13: 0.0017662794 | X13: =S14-S13 -> 0.011156114 | Y13: =T14-T13 -> -0.0016152726 | Z13: =U14-U13 -> -0.0020282668 | AA13: =V14-V13 -> -0.0009523018
B14: 12 | C14: 0.8 | D14: -17.278011 | E14: 2.8002506 | F14: 1.461 | G14: 91.09277 | H14: th2 | J14: 12 | K14: 0.8 | L14: -8.708673 | M14: 4.0333564 | N14: 81.094465 | O14: tc2 | Q14: 12 | R14: 1.025 | S14: 0.00030494103 | T14: -0.0069608246 | U14: 0.0015999459 | V14: 0.00081397761 | X14: =S15-S14 -> 0.011162287 | Y14: =T15-T14 -> -0.0016161665 | Z14: =U15-U14 -> -0.0020293892 | AA14: =V15-V14 -> -0.00095282879
... B22: 20 | C22: 0.825 | D22: -123.86706 | E22: 0.79445649 | F22: 1.243 | G22: 98.74059 | H22: th1 - alt | J22: 20 | K22: 0.85 | L22: -8.708673 | M22: 4.0333564 | N22: 81.094465 | O22: tc2 | Q22: 20 | R22: 1.225 | S22: 0.08977678 | T22: -0.019915283 | U22: -0.014666719 | V22: -0.0068234664 | X22: =S23-S22 -> 0.011211839 | Y22: =T23-T22 -> -0.0016233409 | Z22: =U23-U22 -> -0.002038398 | AA22: =V23-V22 -> -0.00095705857
B23: 21 | C23: 0.85 | D23: 114.72951 | E23: 0.16133392 | F23: 0.074 | G23: -27.923393 | H23: th1 | J23: 21 | K23: 0.875 | L23: 117.67083 | M23: 0.0068110376 | N23: -27.36343 | O23: th1 | Q23: 21 | R23: 1.25 | S23: 0.10098862 | T23: -0.021538624 | U23: -0.016705117 | V23: -0.007780525
B24: 22 | C24: 0.85 | D24: -17.278011 | E24: 2.8002506 | F24: 1.461 | G24: 91.09277 | H24: th2 | J24: 22 | K24: 0.875 | L24: -17.397706 | M24: 4.3921952 | N24: 81.040486 | O24: th2
B25: 23 | C25: 0.85 | D25: -30.318138 | E25: 2.145952 | F25: 1.475 | G25: 92.270089 | H25: tc1 | J25: 23 | K25: 0.875 | L25: -30.532992 | M25: 3.7767751 | N25: 80.158519 | O25: tc1
B26: 24 | C26: 0.85 | D26: -8.6500293 | E26: 2.4847578 | F26: 1.408 | G26: 91.735484 | H26: tc2 | J26: 24 | K26: 0.875 | L26: -8.708673 | M26: 4.0333564 | N26: 81.094465 | O26: tc2
B27: 25 | C27: 0.85 | D27: -123.86706 | E27: 0.7944565 | F27: 1.243 | G27: 98.74059 | H27: th1 - alt | J27: 25 | K27: 0.9 | L27: 117.67083 | M27: 6.4258219e-07 | N27: -27.36343 | O27: th1
B28: 26 | C28: 0.875 | D28: 114.72954 | E28: 0.16152255 | F28: 0.074 | G28: -27.923912 | H28: th1 | J28: 26 | K28: 0.9 | L28: -17.397706 | M28: 4.3921953 | N28: 81.040486 | O28: th2
B29: 27 | C29: 0.875 | D29: -17.278012 | E29: 2.8002506 | F29: 1.461 | G29: 91.09277 | H29: th2 | J29: 27 | K29: 0.9 | L29: -30.532992 | M29: 3.7767751 | N29: 80.158519 | O29: tc1
B30: 28 | C30: 0.875 | D30: -30.318138 | E30: 2.145952 | F30: 1.475 | G30: 92.270089 | H30: tc1 | J30: 28 | K30: 0.9 | L30: -8.708673 | M30: 4.0333564 | N30: 81.094465 | O30: tc2
B31: 29 | C31: 0.875 | D31: -8.6500294 | E31: 2.4847578 | F31: 1.408 | G31: 91.735484 | H31: tc2 | J31: 29 | K31: 0.925 | L31: 117.67128 | M31: 4.7523113e-10 | N31: -27.363499 | O31: th1
B32: 30 | C32: 0.875 | D32: -123.86706 | E32: 0.7944565 | F32: 1.243 | G32: 98.74059 | H32: th1 - alt | J32: 30 | K32: 0.925 | L32: -17.39418 | M32: 4.3927137 | N32: 81.038261 | O32: th2
B33: 31 | C33: 0.9 | D33: 114.72948 | E33: 0.16102216 | F33: 0.078 | G33: -27.924486 | H33: th1 | J33: 31 | K33: 0.925 | L33: -30.530402 | M33: 3.7769452 | N33: 80.157835 | O33: tc1
B34: 32 | C34: 0.9 | D34: -17.278011 | E34: 2.8002506 | F34: 1.461 | G34: 91.09277 | H34: th2 | J34: 32 | K34: 0.925 | L34: -8.7072317 | M34: 4.0337359 | N34: 81.093097 | O34: tc2
B35: 33 | C35: 0.9 | D35: -30.318138 | E35: 2.145952 | F35: 1.475 | G35: 92.270089 | H35: tc1 | J35: 33 | K35: 0.95 | L35: 117.67128 | M35: 4.7523113e-10 | N35: -27.363499 | O35: th1
... B86: 84 | C86: 1.15 | D86: -8.6500293 | E86: 2.4847578 | F86: 1.408 | G86: 91.735484 | H86: tc2 | J86: 84 | K86: 1.25 | L86: -8.7069252 | M86: 4.0338131 | N86: 82.911675 | O86: tc2
B87: 85 | C87: 1.15 | D87: -123.86706 | E87: 0.79445649 | F87: 1.243 | G87: 98.74059 | H87: th1 - alt
B88: 86 | C88: 1.175 | D88: 114.73002 | E88: 0.16138063 | F88: 0.074 | G88: -27.923572 | H88: th1
B89: 87 | C89: 1.175 | D89: -17.274486 | E89: 2.8004272 | F89: 1.462 | G89: 91.091831 | H89: th2
B90: 88 | C90: 1.175 | D90: -30.315551 | E90: 2.146008 | F90: 1.475 | G90: 92.269724 | H90: tc1
B91: 89 | C91: 1.175 | D91: -8.6485893 | E91: 2.484897 | F91: 1.409 | G91: 91.734775 | H91: tc2
B92: 90 | C92: 1.175 | D92: -123.8666 | E92: 0.79445694 | F92: 1.243 | G92: 98.740587 | H92: th1 - alt
B93: 91 | C93: 1.2 | D93: 114.72998 | E93: 0.16086929 | F93: 0.078 | G93: -27.924108 | H93: th1
B94: 92 | C94: 1.2 | D94: -17.274486 | E94: 2.8004272 | F94: 1.462 | G94: 91.091831 | H94: th2
B95: 93 | C95: 1.2 | D95: -30.315551 | E95: 2.146008 | F95: 1.475 | G95: 92.269724 | H95: tc1
B96: 94 | C96: 1.2 | D96: -8.6485893 | E96: 2.484897 | F96: 1.409 | G96: 91.734775 | H96: tc2
B97: 95 | C97: 1.2 | D97: -123.8666 | E97: 0.79445694 | F97: 1.243 | G97: 98.740587 | H97: th1 - alt
...

Sheet Variar Nominales h211
A1: uh211 | B1: Parameter Array (tiempo muerto) | J1: Sin Tiempo Muerto | Q1: error final vs setpoint (en % de sp)
B2: n | C2: Valor | D2: Kp | E2: Tp | F2: Td | G2: % | H2: Salida | J2: n | K2: Valor | L2: Kp | M2: Tp | N2: % | O2: Salida | Q2: n | R2: Valor | S2: th1 | T2: th2 | U2: tc1 | V2: tc2
B3: 1 | C3: 0.75 | D3: -0.00019546183 | E3: 3.5666009 | F3: 4.15 | G3: 87.491055 | H3: th1 | J3: 1 | K3: 0.75 | L3: -0.00019832857 | M3: 7.7593772 | N3: 74.579124 | O3: th1 | Q3: 1 | R3: 0.75 | S3: -0.010851211 | T3: -0.12512889 | U3: 0.13760328 | V3: -0.06885331
B4: 2 | C4: 0.75 | D4: 37.284917 | E4: 0.32917586 | F4: 6.763 | G4: 53.31356 | H4: th2 | J4: 2 | K4: 0.75 | L4: 37.073363 | M4: 4.5872171 | N4: 47.159781 | O4: th2 | Q4: 2 | R4: 0.775 | S4: -0.010851211 | T4: -0.12512889 | U4: 0.13760328 | V4: -0.06885331
B5: 3 | C5: 0.75 | D5: -56.858032 | E5: 2.9753538 | F5: 6.737 | G5: 91.545144 | H5: tc1 | J5: 3 | K5: 0.75 | L5: -58.489101 | M5: 10.38511 | N5: 64.372808 | O5: tc1 | Q5: 3 | R5: 0.8 | S5: -0.010851211 | T5: -0.12512889 | U5: 0.13760328 | V5: -0.06885331
B6: 4 | C6: 0.75 | D6: 18.812884 | E6: 1.5828467 | F6: 1.808 | G6: 50.970123 | H6: tc2 | J6: 4 | K6: 0.75 | L6: 18.772289 | M6: 2.8288887 | N6: 44.104166 | O6: tc2 | Q6: 4 | R6: 0.825 | S6: -0.010851211 | T6: -0.12512889 | U6: 0.13760328 | V6: -0.06885331
B7: 5 | C7: 0.75 | D7: -0.00019546183 | E7: 3.5666009 | F7: 4.15 | G7: 87.491055 | H7: th1 - alt | J7: 5 | K7: 0.775 | L7: -6.7316288e-05 | M7: 8.3962643 | N7: 72.506939 | O7: th1 | Q7: 5 | R7: 0.85 | S7: -0.010851211 | T7: -0.12512889 | U7: 0.13760328 | V7: -0.06885331
B8: 6 | C8: 0.775 | D8: -6.6141458e-05 | E8: 3.2750687 | F8: 5.069 | G8: 86.653846 | H8: th1 | J8: 6 | K8: 0.775 | L8: 37.069097 | M8: 4.6939313 | N8: 46.940712 | O8: th2 | Q8: 6 | R8: 0.875 | S8: -0.010851211 | T8: -0.12512889 | U8: 0.13760328 | V8: -0.06885331
B9: 7 | C9: 0.775 | D9: 37.136623 | E9: 1.5082764 | F9: 4.564 | G9: 54.764233 | H9: th2 | J9: 7 | K9: 0.775 | L9: -58.503884 | M9: 10.571474 | N9: 64.055742 | O9: tc1 | Q9: 7 | R9: 0.9 | S9: -0.010851211 | T9: -0.12512889 | U9: 0.13760328 | V9: -0.06885331
B10: 8 | C10: 0.775 | D10: -56.764338 | E10: 2.4829882 | F10: 7.439 | G10: 91.415645 | H10: tc1 | J10: 8 | K10: 0.775 | L10: 18.757627 | M10: 2.9199692 | N10: 44.258061 | O10: tc2 | Q10: 8 | R10: 0.925 | S10: -0.010851211 | T10: -0.12512889 | U10: 0.13760328 | V10: -0.06885331
B11: 9 | C11: 0.775 | D11: 18.795221 | E11: 1.6734671 | F11: 1.803 | G11: 50.813387 | H11: tc2 | J11: 9 | K11: 0.8 | L11: -0.00019832725 | M11: 7.7593132 | N11: 74.579132 | O11: th1 | Q11: 9 | R11: 0.95 | S11: -0.010851211 | T11: -0.12512889 | U11: 0.13760328 | V11: -0.06885331
B12: 10 | C12: 0.775 | D12: -6.6141458e-05 | E12: 3.2750687 | F12: 5.069 | G12: 86.653846 | H12: th1 - alt | J12: 10 | K12: 0.8 | L12: 37.073365 | M12: 4.5871749 | N12: 47.159735 | O12: th2 | Q12: 10 | R12: 0.975 | S12: -0.010851211 | T12: -0.12512889 | U12: 0.13760328 | V12: -0.06885331
B13: 11 | C13: 0.8 | D13: -0.00019546055 | E13: 3.5665497 | F13: 4.15 | G13: 87.491134 | H13: th1 | J13: 11 | K13: 0.8 | L13: -58.489073 | M13: 10.385019 | N13: 64.372904 | O13: tc1 | Q13: 11 | R13: 1 | S13: -0.010851211 | T13: -0.12512889 | U13: 0.13760328 | V13: -0.06885331
B14: 12 | C14: 0.8 | D14: 37.284924 | E14: 0.32912238 | F14: 6.763 | G14: 53.313442 | H14: th2 | J14: 12 | K14: 0.8 | L14: 18.772287 | M14: 2.8288744 | N14: 44.104173 | O14: tc2 | Q14: 12 | R14: 1.025 | S14: -0.010851211 | T14: -0.12512889 | U14: 0.13760328 | V14: -0.06885331
... B23: 21 | C23: 0.85 | D23: -6.6128125e-05 | E23: 3.1722217 | F23: 5.045 | G23: 85.617421 | H23: th1 | J23: 21 | K23: 0.875 | L23: -6.7294986e-05 | M23: 8.2209412 | N23: 72.957942 | O23: th1 | Q23: 21 | R23: 1.25 | S23: -0.010851211 | T23: -0.12512889 | U23: 0.13760328 | V23: -0.06885331
B24: 22 | C24: 0.85 | D24: 37.285902 | E24: 0.32914671 | F24: 6.763 | G24: 53.314648 | H24: th2 | J24: 22 | K24: 0.875 | L24: 37.07436 | M24: 4.5871866 | N24: 47.160628 | O24: th2
B25: 23 | C25: 0.85 | D25: -56.857287 | E25: 2.9753034 | F25: 6.737 | G25: 91.545363 | H25: tc1 | J25: 23 | K25: 0.875 | L25: -58.488285 | M25: 10.384901 | N25: 64.372874 | O25: tc1
B26: 24 | C26: 0.85 | D26: 18.813275 | E26: 1.5828647 | F26: 1.808 | G26: 50.971426 | H26: tc2 | J26: 24 | K26: 0.875 | L26: 18.772676 | M26: 2.8288937 | N26: 44.105396 | O26: tc2 | Q26: error final vs setpoint (en % de sp)
B27: 25 | C27: 0.85 | D27: -6.6128125e-05 | E27: 3.1722217 | F27: 5.045 | G27: 85.617421 | H27: th1 - alt | J27: 25 | K27: 0.9 | L27: -3.9903267e-05 | M27: 8.5453136 | N27: 73.474196 | O27: th1 | Q27: n | R27: Valor | S27: th1 | T27: th2 | U27: tc1 | V27: tc2
B28: 26 | C28: 0.875 | D28: -6.613009e-05 | E28: 3.1721384 | F28: 5.044 | G28: 85.617214 | H28: th1 | J28: 26 | K28: 0.9 | L28: 37.069278 | M28: 4.6939468 | N28: 50.220663 | O28: th2 | Q28: 1 | R28: 0.75 | S28: -0.010851211 | T28: -0.12512889 | U28: 0.13760328 | V28: -0.06885331 | X28: =S29-S28 -> 0 | Y28: =T29-T28 -> 0.011852873 | Z28: =U29-U28 -> -0.013257181 | AA28: =V29-V28 -> 0.0069879922
B29: 27 | C29: 0.875 | D29: 37.285907 | E29: 0.32906563 | F29: 6.763 | G29: 53.31449 | H29: th2 | J29: 27 | K29: 0.9 | L29: -58.503694 | M29: 10.57148 | N29: 65.592191 | O29: tc1 | Q29: 2 | R29: 0.775 | S29: -0.010851211 | T29: -0.11327601 | U29: 0.1243461 | V29: -0.061865318 | X29: =S30-S29 -> -1.4798926e-14 | Y29: =T30-T29 -> 0.011880597 | Z29: =U30-U29 -> -0.01328819 | AA29: =V30-V29 -> 0.0070043373
B30: 28 | C30: 0.875 | D30: -56.857266 | E30: 2.9752081 | F30: 6.737 | G30: 91.545601 | H30: tc1 | J30: 28 | K30: 0.9 | L30: 18.757712 | M30: 2.9199801 | N30: 48.506465 | O30: tc2 | Q30: 3 | R30: 0.8 | S30: -0.010851211 | T30: -0.10139542 | U30: 0.11105791 | V30: -0.054860981 | X30: =S31-S30 -> 0 | Y30: =T31-T30 -> 0.011908231 | Z30: =U31-U30 -> -0.013319098 | AA30: =V31-V30 -> 0.0070206291
B31: 29 | C31: 0.875 | D31: 18.813268 | E31: 1.5828372 | F31: 1.808 | G31: 50.971659 | H31: tc2 | J31: 29 | K31: 0.925 | L31: -0.0001983927 | M31: 7.9317681 | N31: 74.10707 | O31: th1 | Q31: 4 | R31: 0.825 | S31: -0.010851211 | T31: -0.089487187 | U31: 0.097738817 | V31: -0.047840352 | X31: =S32-S31 -> 1.4798926e-14 | Y31: =T32-T31 -> 0.011936044 | Z31: =U32-U31 -> -0.013350205 | AA31: =V32-V31 -> 0.0070370264
B32: 30 | C32: 0.875 | D32: -6.613009e-05 | E32: 3.1721384 | F32: 5.044 | G32: 85.617214 | H32: th1 - alt | J32: 30 | K32: 0.925 | L32: 37.0681 | M32: 4.6938571 | N32: 46.939854 | O32: th2 | Q32: 5 | R32: 0.85 | S32: -0.010851211 | T32: -0.077551144 | U32: 0.084388611 | V32: -0.040803325 | X32: =S33-S32 -> 0 | Y32: =T33-T32 -> 0.011964036 | Z32: =U33-U32 -> -0.013381515 | AA32: =V33-V32 -> 0.0070535298
B33: 31 | C33: 0.9 | D33: -3.9243597e-05 | E33: 3.8051207 | F33: 4.574 | G33: 88.960856 | H33: th1 | J33: 31 | K33: 0.925 | L33: -58.504628 | M33: 10.571441 | N33: 64.05587 | O33: tc1 | Q33: 6 | R33: 0.875 | S33: -0.010851211 | T33: -0.065587107 | U33: 0.071007097 | V33: -0.033749795 | X33: =S34-S33 -> -1.4798926e-14 | Y33: =T34-T33 -> 0.011991938 | Z33: =U34-U33 -> -0.013412723 | AA33: =V34-V33 -> 0.0070699798
B34: 32 | C34: 0.9 | D34: 37.136801 | E34: 1.5082815 | F34: 4.564 | G34: 57.560637 | H34: th2 | J34: 32 | K34: 0.925 | L34: 18.757231 | M34: 2.9199179 | N34: 44.25702 | O34: tc2 | Q34: 7 | R34: 0.9 | S34: -0.010851211 | T34: -0.053595169 | U34: 0.057594374 | V34: -0.026679816 | X34: =S35-S34 -> 0 | Y34: =T35-T34 -> 0.012020021 | Z34: =U35-U34 -> -0.013444132 | AA34: =V35-V34 -> 0.0070865362
B35: 33 | C35: 0.9 | D35: -56.764151 | E35: 2.4829887 | F35: 7.439 | G35: 91.782623 | H35: tc1 | J35: 33 | K35: 0.95 | L35: -0.00019832576 | M35: 7.7593146 | N35: 74.579128 | O35: th1 | Q35: 8 | R35: 0.925 | S35: -0.010851211 | T35: -0.041575148 | U35: 0.044150242 | V35: -0.019593279 | X35: =S36-S35 -> 1.4798926e-14 | Y35: =T36-T35 -> 0.012048285 | Z35: =U36-U35 -> -0.013475745 | AA35: =V36-V35 -> 0.0071031998
B36: 34 | C36: 0.9 | D36: 18.795305 | E36: 1.6734741 | F36: 1.803 | G36: 54.562229 | H36: tc2 | J36: 34 | K36: 0.95 | L36: 37.073365 | M36: 4.587177 | N36: 47.159744 | O36: th2 | Q36: 9 | R36: 0.95 | S36: -0.010851211 | T36: -0.029526863 | U36: 0.030674496 | V36: -0.01249008 | X36: =S37-S36 -> -1.4798926e-14 | Y36: =T37-T36 -> 0.012076459 | Z36: =U37-U36 -> -0.013507257 | AA36: =V37-V36 -> 0.0071198098
B37: 35 | C37: 0.9 | D37: -3.9241863e-05 | E37: 3.8051207 | F37: 4.574 | G37: 88.962486 | H37: th1 - alt | J37: 35 | K37: 0.95 | L37: -58.489074 | M37: 10.38502 | N37: 64.372895 | O37: tc1 | Q37: 10 | R37: 0.975 | S37: -0.010851211 | T37: -0.017450404 | U37: 0.01716724 | V37: -0.0053702698 | X37: =S38-S37 -> 1.4798926e-14 | Y37: =T38-T37 -> 0.012104814 | Z37: =U38-U37 -> -0.013538972 | AA37: =V38-V37 -> 0.0071365272
B38: 36 | C38: 0.925 | D38: -0.00019544779 | E38: 3.5688174 | F38: 4.308 | G38: 87.765714 | H38: th1 | J38: 36 | K38: 0.95 | L38: 18.772286 | M38: 2.8288748 | N38: 44.104193 | O38: tc2 | Q38: 11 | R38: 1 | S38: -0.010851211 | T38: -0.0053455894 | U38: 0.0036282676 | V38: 0.0017662574 | X38: =S39-S38 -> 0 | Y38: =T39-T38 -> 0.012133354 | Z38: =U39-U38 -> -0.013570892 | AA38: =V39-V38 -> 0.0071533527
B39: 37 | C39: 0.925 | D39: 37.135641 | E39: 1.5082526 | F39: 4.564 | G39: 54.763092 | H39: th2 | J39: 37 | K39: 0.975 | L39: -3.9890442e-05 | M39: 8.3688879 | N39: 73.921972 | O39: th1 | Q39: 12 | R39: 1.025 | S39: -0.010851211 | T39: 0.0067877641 | U39: -0.0099426247 | V39: 0.00891961 | X39: =S40-S39 -> 0 | Y39: =T40-T39 -> 0.012161802 | Z39: =U40-U39 -> -0.013602711 | AA39: =V40-V39 -> 0.0071701245
... B47: 45 | C47: 0.95 | D47: -0.00019545908 | E47: 3.5665503 | F47: 4.15 | G47: 87.491119 | H47: th1 - alt | J47: 45 | K47: 1.025 | L47: -0.00019838959 | M47: 7.9318741 | N47: 74.10712 | O47: th1 | Q47: 20 | R47: 1.225 | S47: -0.010851211 | T47: 0.10488928 | U47: -0.11966704 | V47: 0.066756441 | X47: =S48-S47 -> -1.4798926e-14 | Y47: =T48-T47 -> 0.012393569 | Z47: =U48-U47 -> -0.013861937 | AA47: =V48-V47 -> 0.0073067654
B48: 46 | C48: 0.975 | D48: -3.9244269e-05 | E48: 3.7781724 | F48: 4.445 | G48: 88.803683 | H48: th1 | J48: 46 | K48: 1.025 | L48: 37.068123 | M48: 4.6939059 | N48: 46.939653 | O48: th2 | Q48: 21 | R48: 1.25 | S48: -0.010851211 | T48: 0.11728285 | U48: -0.13352897 | V48: 0.074063207
B49: 47 | C49: 0.975 | D49: 37.286079 | E49: 0.32915143 | F49: 6.763 | G49: 56.239182 | H49: th2 | J49: 47 | K49: 1.025 | L49: -58.504672 | M49: 10.571605 | N49: 64.05589 | O49: tc1
B50: 48 | C50: 0.975 | D50: -56.857101 | E50: 2.9753041 | F50: 6.737 | G50: 91.912953 | H50: tc1 | J50: 48 | K50: 1.025 | L50: 18.757247 | M50: 2.9199464 | N50: 44.256843 | O50: tc2
B51: 49 | C51: 0.975 | D51: 18.813358 | E51: 1.5828713 | F51: 1.808 | G51: 54.745166 | H51: tc2 | J51: 49 | K51: 1.05 | L51: -3.9890684e-05 | M51: 8.3688889 | N51: 73.92137 | O51: th1
B52: 50 | C52: 0.975 | D52: -3.9241751e-05 | E52: 3.7781724 | F52: 4.445 | G52: 88.806057 | H52: th1 - alt | J52: 50 | K52: 1.05 | L52: 37.074541 | M52: 4.5872017 | N52: 50.470596 | O52: th2
B53: 51 | C53: 1 | D53: -0.00019545909 | E53: 3.5665502 | F53: 4.15 | G53: 87.491119 | H53: th1 | J53: 51 | K53: 1.05 | L53: -58.488095 | M53: 10.384908 | N53: 65.921817 | O53: tc1
B54: 52 | C54: 1 | D54: 37.284923 | E54: 0.329124 | F54: 6.763 | G54: 53.313457 | H54: th2 | J54: 52 | K54: 1.05 | L54: 18.77276 | M54: 2.8289041 | N54: 48.40758 | O54: tc2
B55: 53 | C55: 1 | D55: -56.858019 | E55: 2.9752999 | F55: 6.737 | G55: 91.545303 | H55: tc1 | J55: 53 | K55: 1.075 | L55: -0.00019832577 | M55: 7.7593148 | N55: 74.579127 | O55: th1
...

Sheet Variar Nominales h222
A1: uh222 | B1: Parameter Array (tiempo muerto) | J1: Sin Tiempo Muerto | Q1: error final vs setpoint (en % de sp)
B2: n | C2: Valor | D2: Kp | E2: Tp | F2: Td | G2: % | H2: Salida | J2: n | K2: Valor | L2: Kp | M2: Tp | N2: % | O2: Salida | Q2: n | R2: Valor | S2: th1 | T2: th2 | U2: tc1 | V2: tc2
B3: 1 | C3: 0.75 | D3: -0.00012636417 | E3: 3.2325003 | F3: 13.23 | G3: 87.534655 | H3: th1 | J3: 1 | K3: 0.75 | L3: -0.00013554797 | M3: 18.852914 | N3: 61.347378 | O3: th1 | Q3: 1 | R3: 0.75 | S3: -0.010851211 | T3: -0.18784202 | U3: 0.0036282196 | V3: 0.11830341 | X3: =S4-S3 -> 1.4798926e-14 | Y3: =T4-T3 -> 0.01795397 | Z3: =U4-U3 -> 0 | AA3: =V4-V3 -> -0.011464902
B4: 2 | C4: 0.75 | D4: 39.170145 | E4: 0.16133501 | F4: 8.739 | G4: 19.935073 | H4: th2 | J4: 2 | K4: 0.75 | L4: 39.998502 | M4: 4.051827 | N4: 12.347214 | O4: th2 | Q4: 2 | R4: 0.775 | S4: -0.010851211 | T4: -0.16988805 | U4: 0.0036282196 | V4: 0.10683851 | X4: =S5-S4 -> -1.4798926e-14 | Y4: =T5-T4 -> 0.018018753 | Z4: =U5-U4 -> 0 | AA4: =V5-V4 -> -0.01150627
B5: 3 | C5: 0.75 | D5: -0.00080944239 | E5: 2.946173 | F5: 14.048 | G5: 87.908032 | H5: tc1 | J5: 3 | K5: 0.75 | L5: -0.00087518281 | M5: 19.839957 | N5: 60.298096 | O5: tc1 | Q5: 3 | R5: 0.8 | S5: -0.010851211 | T5: -0.1518693 | U5: 0.0036282196 | V5: 0.095332242 | X5: =S6-S5 -> 1.4798926e-14 | Y5: =T6-T5 -> 0.018083878 | Z5: =U6-U5 -> 0 | AA5: =V6-V5 -> -0.011547858
B6: 4 | C6: 0.75 | D6: -19.343079 | E6: 0.18456509 | F6: 18.236 | G6: 60.768454 | H6: tc2 | J6: 4 | K6: 0.75 | L6: -20.899639 | M6: 19.056312 | N6: 56.39902 | O6: tc2 | Q6: 4 | R6: 0.825 | S6: -0.010851211 | T6: -0.13378542 | U6: 0.0036282196 | V6: 0.083784385 | X6: =S7-S6 -> -1.4798926e-14 | Y6: =T7-T6 -> 0.018149348 | Z6: =U7-U6 -> 0 | AA6: =V7-V6 -> -0.011589665
B7: 5 | C7: 0.75 | D7: -0.00012636417 | E7: 3.2325003 | F7: 13.23 | G7: 87.534655 | H7: th1 - alt | J7: 5 | K7: 0.775 | L7: -4.6165486e-05 | M7: 19.641732 | N7: 60.380539 | O7: th1 | Q7: 5 | R7: 0.85 | S7: -0.010851211 | T7: -0.11563607 | U7: 0.0036282196 | V7: 0.07219472 | X7: =S8-S7 -> 0 | Y7: =T8-T7 -> 0.018215165 | Z7: =U8-U7 -> 0 | AA7: =V8-V7 -> -0.011631694
B8: 6 | C8: 0.775 | D8: -4.2758023e-05 | E8: 2.8844934 | F8: 14.037 | G8: 87.437525 | H8: th1 | J8: 6 | K8: 0.775 | L8: 39.999079 | M8: 4.0518603 | N8: 12.347645 | O8: th2 | Q8: 6 | R8: 0.875 | S8: -0.010851211 | T8: -0.097420909 | U8: 0.0036282196 | V8: 0.060563027 | X8: =S9-S8 -> 1.4798926e-14 | Y8: =T9-T8 -> 0.018281331 | Z8: =U9-U8 -> 0 | AA8: =V9-V8 -> -0.011673946
B9: 7 | C9: 0.775 | D9: 39.171019 | E9: 0.15966233 | F9: 8.742 | G9: 19.935174 | H9: th2 | J9: 7 | K9: 0.775 | L9: -0.00036525392 | M9: 20.754478 | N9: 58.678896 | O9: tc1 | Q9: 7 | R9: 0.9 | S9: -0.010851211 | T9: -0.079139577 | U9: 0.0036282196 | V9: 0.048889081 | X9: =S10-S9 -> -1.4798926e-14 | Y9: =T10-T9 -> 0.01834785 | Z9: =U10-U9 -> 0 | AA9: =V10-V9 -> -0.011716422
B10: 8 | C10: 0.775 | D10: -0.00033497365 | E10: 2.3904763 | F10: 15.015 | G10: 88.170249 | H10: tc1 | J10: 8 | K10: 0.775 | L10: -20.899356 | M10: 19.05632 | N10: 56.39897 | O10: tc2 | Q10: 8 | R10: 0.925 | S10: -0.010851211 | T10: -0.060791728 | U10: 0.0036282196 | V10: 0.037172659 | X10: =S11-S10 -> 0 | Y10: =T11-T10 -> 0.018414722 | Z10: =U11-U10 -> 0 | AA10: =V11-V10 -> -0.011759125
B11: 9 | C11: 0.775 | D11: -19.342816 | E11: 0.18496197 | F11: 18.234 | G11: 60.768495 | H11: tc2 | J11: 9 | K11: 0.8 | L11: -2.740195e-05 | M11: 19.906673 | N11: 61.031553 | O11: th1 | Q11: 9 | R11: 0.95 | S11: -0.010851211 | T11: -0.042377006 | U11: 0.0036282196 | V11: 0.025413534 | X11: =S12-S11 -> 0 | Y11: =T12-T11 -> 0.018481951 | Z11: =U12-U11 -> 0 | AA11: =V12-V11 -> -0.011802056
B12: 10 | C12: 0.775 | D12: -4.2758023e-05 | E12: 2.8844934 | F12: 14.037 | G12: 87.437525 | H12: th1 - alt | J12: 10 | K12: 0.8 | L12: 39.999181 | M12: 4.0518662 | N12: 14.01977 | O12: th2 | Q12: 10 | R12: 0.975 | S12: -0.010851211 | T12: -0.023895054 | U12: 0.0036282196 | V12: 0.013611478 | X12: =S13-S12 -> 1.4798926e-14 | Y12: =T13-T12 -> 0.01854954 | Z12: =U13-U12 -> 0 | AA12: =V13-V12 -> -0.011845216
B13: 11 | C13: 0.8 | D13: -2.5421932e-05 | E13: 4.0869364 | F13: 12.776 | G13: 89.087015 | H13: th1 | J13: 11 | K13: 0.8 | L13: -0.00023444879 | M13: 21.194425 | N13: 58.944896 | O13: tc1 | Q13: 11 | R13: 1 | S13: -0.010851211 | T13: -0.0053455147 | U13: 0.0036282196 | V13: 0.0017662624 | X13: =S14-S13 -> -1.4798926e-14 | Y13: =T14-T13 -> 0.01861749 | Z13: =U14-U13 -> 0 | AA13: =V14-V13 -> -0.011888607
B14: 12 | C14: 0.8 | D14: 39.171091 | E14: 0.15928159 | F14: 8.743 | G14: 21.461405 | H14: th2 | J14: 12 | K14: 0.8 | L14: -20.899295 | M14: 19.056317 | N14: 57.480675 | O14: tc2 | Q14: 12 | R14: 1.025 | S14: -0.010851211 | T14: 0.013271975 | U14: 0.0036282196 | V14: -0.010122344 | X14: =S15-S14 -> 1.4798926e-14 | Y14: =T15-T14 -> 0.018685712 | Z14: =U15-U14 -> 0 | AA14: =V15-V14 -> -0.011932172
... B22: 20 | C22: 0.825 | D22: -4.2758023e-05 | E22: 2.8844932 | F22: 14.037 | G22: 87.437528 | H22: th1 - alt | J22: 20 | K22: 0.85 | L22: -20.899642 | M22: 19.056333 | N22: 56.399024 | O22: tc2 | Q22: 20 | R22: 1.225 | S22: -0.010851211 | T22: 0.16470223 | U22: 0.0036282196 | V22: -0.10682146 | X22: =S23-S22 -> 0 | Y22: =T23-T22 -> 0.019245733 | Z22: =U23-U22 -> -2.0300168e-14 | AA22: =V23-V22 -> -0.012289785
B23: 21 | C23: 0.85 | D23: -0.00012636558 | E23: 3.2325125 | F23: 13.23 | G23: 87.53466 | H23: th1 | J23: 21 | K23: 0.875 | L23: -2.740195e-05 | M23: 19.906672 | N23: 61.031555 | O23: th1 | Q23: 21 | R23: 1.25 | S23: -0.010851211 | T23: 0.18394796 | U23: 0.0036282196 | V23: -0.11911124
B24: 22 | C24: 0.85 | D24: 39.170284 | E24: 0.15858482 | F24: 8.743 | G24: 19.936829 | H24: th2 | J24: 22 | K24: 0.875 | L24: 39.999181 | M24: 4.0518662 | N24: 14.01977 | O24: th2
B25: 23 | C25: 0.85 | D25: -0.00080943842 | E25: 2.9461864 | F25: 14.048 | G25: 87.908107 | H25: tc1 | J25: 23 | K25: 0.875 | L25: -0.00023444878 | M25: 21.194424 | N25: 58.944897 | O25: tc1
B26: 24 | C26: 0.85 | D26: -19.343079 | E26: 0.18446066 | F26: 18.236 | G26: 60.768593 | H26: tc2 | J26: 24 | K26: 0.875 | L26: -20.899295 | M26: 19.056317 | N26: 57.480675 | O26: tc2
B27: 25 | C27: 0.85 | D27: -0.00012636558 | E27: 3.2325125 | F27: 13.23 | G27: 87.53466 | H27: th1 - alt | J27: 25 | K27: 0.9 | L27: -0.0001355495 | M27: 18.852935 | N27: 61.347386 | O27: th1
B28: 26 | C28: 0.875 | D28: -2.5421932e-05 | E28: 4.0869362 | F28: 12.776 | G28: 89.087012 | H28: th1 | J28: 26 | K28: 0.9 | L28: 39.998509 | M28: 4.051829 | N28: 12.347211 | O28: th2
B29: 27 | C29: 0.875 | D29: 39.171076 | E29: 0.15888776 | F29: 8.744 | G29: 21.460267 | H29: th2 | J29: 27 | K29: 0.9 | L29: -0.00087517879 | M29: 19.840005 | N29: 60.298066 | O29: tc1
B30: 28 | C30: 0.875 | D30: -0.00021427204 | E30: 2.3903124 | F30: 15.124 | G30: 89.860937 | H30: tc1 | J30: 28 | K30: 0.9 | L30: -20.899642 | M30: 19.056333 | N30: 56.399024 | O30: tc2
B31: 29 | C31: 0.875 | D31: -19.34276 | E31: 0.18509571 | F31: 18.234 | G31: 61.741787 | H31: tc2 | J31: 29 | K31: 0.925 | L31: -0.0001355495 | M31: 18.852934 | N31: 61.347386 | O31: th1
B32: 30 | C32: 0.875 | D32: -2.5420506e-05 | E32: 4.0869362 | F32: 12.776 | G32: 89.089369 | H32: th1 - alt | J32: 30 | K32: 0.925 | L32: 39.998509 | M32: 4.051829 | N32: 12.347211 | O32: th2
B33: 31 | C33: 0.9 | D33: -0.00012636558 | E33: 3.2325125 | F33: 13.23 | G33: 87.53466 | H33: th1 | J33: 31 | K33: 0.925 | L33: -0.0008751788 | M33: 19.840005 | N33: 60.298066 | O33: tc1
B34: 32 | C34: 0.9 | D34: 39.170279 | E34: 0.15845955 | F34: 8.744 | G34: 19.934267 | H34: th2 | J34: 32 | K34: 0.925 | L34: -20.899642 | M34: 19.056333 | N34: 56.399024 | O34: tc2
B35: 33 | C35: 0.9 | D35: -0.00080943842 | E35: 2.9461863 | F35: 14.048 | G35: 87.908107 | H35: tc1 | J35: 33 | K35: 0.95 | L35: -2.740195e-05 | M35: 19.906673 | N35: 61.031554 | O35: th1
... B86: 84 | C86: 1.15 | D86: -19.342816 | E86: 0.18496197 | F86: 18.234 | G86: 60.768495 | H86: tc2 | J86: 84 | K86: 1.25 | L86: -20.899642 | M86: 19.056333 | N86: 56.399024 | O86: tc2
B87: 85 | C87: 1.15 | D87: -4.2758023e-05 | E87: 2.8844931 | F87: 14.037 | G87: 87.437526 | H87: th1 - alt
B88: 86 | C88: 1.175 | D88: -0.00012636558 | E88: 3.2325124 | F88: 13.23 | G88: 87.53466 | H88: th1
B89: 87 | C89: 1.175 | D89: 39.170295 | E89: 0.15890416 | F89: 8.743 | G89: 19.93515 | H89: th2
B90: 88 | C90: 1.175 | D90: -0.00080943842 | E90: 2.9461864 | F90: 14.048 | G90: 87.908107 | H90: tc1
B91: 89 | C91: 1.175 | D91: -19.343079 | E91: 0.18446066 | F91: 18.236 | G91: 60.768593 | H91: tc2
B92: 90 | C92: 1.175 | D92: -0.00012636558 | E92: 3.2325124 | F92: 13.23 | G92: 87.53466 | H92: th1 - alt
B93: 91 | C93: 1.2 | D93: -2.5422135e-05 | E93: 4.0869381 | F93: 12.776 | G93: 89.086681 | H93: th1
B94: 92 | C94: 1.2 | D94: 39.171078 | E94: 0.15896795 | F94: 8.743 | G94: 21.463024 | H94: th2
B95: 93 | C95: 1.2 | D95: -0.00021427647 | E95: 2.3903113 | F95: 15.124 | G95: 89.86054 | H95: tc1
B96: 94 | C96: 1.2 | D96: -19.34276 | E96: 0.18509963 | F96: 18.234 | G96: 61.741778 | H96: tc2
B97: 95 | C97: 1.2 | D97: -2.5420503e-05 | E97: 4.0869381 | F97: 12.776 | G97: 89.089377 | H97: th1 - alt
...

Sheet Variar Nominales c112
A1: uc112 | B1: Parameter Array (tiempo muerto) | J1: Sin Tiempo Muerto | Q1: error final vs setpoint (en % de sp)
B2: n | C2: Valor | D2: Kp | E2: Tp | F2: Td | G2: % | H2: Salida | J2: n | K2: Valor | L2: Kp | M2: Tp | N2: % | O2: Salida | Q2: n | R2: Valor | S2: th1 | T2: th2 | U2: tc1 | V2: tc2
B3: 1 | C3: 0.0025 | D3: 30.637294 | E3: 1.6338775 | F3: 3.359 | G3: 88.29078 | H3: th1 | J3: 1 | K3: 0.0025 | L3: 30.975137 | M3: 4.9560417 | N3: 74.580741 | O3: th1 | Q3: 1 | R3: 0.0025 | S3: 0.0090221837 | T3: -0.0082229777 | U3: 1.5084494e-05 | V3: 6.9861312e-05 | X3: =S4-S3 -> 0.019979332 | Y3: =T4-T3 -> -0.0028927697 | Z3: =U4-U3 -> -0.0036323954 | AA3: =V4-V3 -> -0.0017054643
